Workbook

Sheet README
A1: Fairway Forward — Golf Simulator + Community Golf Academy
A2: Financial model v1 · Hampton Roads, VA · prepared Sept 2026 · all figures are planning estimates, not quotes
A4: How to use | B4: Edit only the BLUE cells on the Assumptions, Startup, Membership Tiers and Foundation sheets. Everything in black recalculates. Yellow-shaded cells are the levers that move the answer the most.
A5: Sheets | B5: Assumptions → Startup → P&L 2-Bay / P&L 3-Bay / P&L 4-Bay → Summary → Membership Tiers → Foundation (education arm) → Sensitivity
A6: Structure | B6: Two entities. OpCo (for-profit LLC) runs the simulator lounge, F&B, memberships. The Foundation (501(c)(3), or fiscally sponsored in year 1) runs the school and youth programs and BUYS bay time from OpCo at a contracted rate. OpCo never gives bay time away; the Foundation raises the money that pays for it.
A7: Why 3 sheets | B7: Fixed costs (GM, kitchen, ABC license, lease minimum) do not scale down with bay count. Compare 2, 3 and 4 bays on the Summary sheet before deciding. The model's opinion: 2 bays with a kitchen and ABC license does not clear debt service; 4 bays does.
A8: Colour code | B8: Blue = hardcoded input. Black = formula. Green = link to another sheet. Yellow fill = key assumption.
A9: Sources | B9: Simulator package pricing: 2025-26 commercial quotes for Foresight GCQuad/GCHawk and Trackman iO class bays incl. enclosure, projector, turf, PC and software ($40k-$75k/bay). Lease: Hampton Roads flex/retail asking rents $14-$22/sf NNN (CoStar/LoopNet 2026 listings). Utilization and F&B attach rates: operator benchmarks for 3-6 bay lounges in secondary metros (25-45% of 14-hr day at maturity; F&B 25-35% of revenue once a mixed-beverage license is in place). All should be re-underwritten with Timmons/site-specific bids before financing.
A10: Verify before relying on | B10: Virginia ABC food-to-alcohol ratio for a mixed beverage restaurant license (historically 45% food + non-alcoholic beverage minimum) and current license fees. SBA 7(a) rate at time of application. Local TI allowance.

Sheet Summary
A1: Scenario Summary — 2 vs 3 vs 4 Bays
A2: Same assumptions, different bay count. Read this sheet first.
A4: Metric | B4: 2 Bays | C4: 3 Bays | D4: 4 Bays | E4: Read
A5: Total project cost | B5: =Startup!C25 -> 826318.36 | C5: =Startup!D25 -> 980344.99 | D5: =Startup!E25 -> 1134371.6 | E5: Includes 6 months working capital and 10% contingency
A6: Owner equity required | B6: =Startup!C29 -> 165263.67 | C6: =Startup!D29 -> 196069 | D6: =Startup!E29 -> 226874.33
A7: SBA loan | B7: =Startup!C30 -> 613054.69 | C7: =Startup!D30 -> 712276 | D7: =Startup!E30 -> 811497.3
A8: Annual debt service | B8: =Startup!C31 -> 100845.84 | C8: =Startup!D31 -> 117167.48 | D8: =Startup!E31 -> 133489.12
A9: Square feet | B9: =Startup!C33 -> 3200 | C9: =Startup!D33 -> 4050 | D9: =Startup!E33 -> 4900
A10: Year 1 revenue | B10: ='P&L 2-Bay'!C27 -> 282516.32 | C10: ='P&L 3-Bay'!C27 -> 423774.48 | D10: ='P&L 4-Bay'!C27 -> 565032.64
A11: Year 3 revenue (mature) | B11: ='P&L 2-Bay'!E27 -> 547133.45 | C11: ='P&L 3-Bay'!E27 -> 813061.69 | D11: ='P&L 4-Bay'!E27 -> 1078989.9 | E11: Benchmark: $200-300k per bay in a healthy market
A12: Year 3 revenue per bay | B12: ='P&L 2-Bay'!E68 -> 273566.72 | C12: ='P&L 3-Bay'!E68 -> 271020.56 | D12: ='P&L 4-Bay'!E68 -> 269747.48
A13: Year 1 EBITDA | B13: ='P&L 2-Bay'!C52 -> -170382.73 | C13: ='P&L 3-Bay'!C52 -> -125608.99 | D13: ='P&L 4-Bay'!C52 -> -80835.251
A14: Year 3 EBITDA | B14: ='P&L 2-Bay'!E52 -> -25241.18 | C14: ='P&L 3-Bay'!E52 -> 97828.873 | D14: ='P&L 4-Bay'!E52 -> 220898.93
A15: Year 3 EBITDA margin | B15: ='P&L 2-Bay'!E53 -> -0.046133499 | C15: ='P&L 3-Bay'!E53 -> 0.12032159 | D15: ='P&L 4-Bay'!E53 -> 0.20472751 | E15: Well-run lounges: 25-35%
A16: Year 1 DSCR | B16: ='P&L 2-Bay'!C67 -> -1.7455658 | C16: ='P&L 3-Bay'!C67 -> -1.144383 | D16: ='P&L 4-Bay'!C67 -> -0.69021284
A17: Year 2 DSCR | B17: ='P&L 2-Bay'!D67 -> -0.87625086 | C17: ='P&L 3-Bay'!D67 -> -0.020598312 | D17: ='P&L 4-Bay'!D67 -> 0.62581395 | E17: Lender threshold ≈ 1.25x
A18: Year 3 DSCR | B18: ='P&L 2-Bay'!E67 -> -0.35880358 | C18: ='P&L 3-Bay'!E67 -> 0.69616278 | D18: ='P&L 4-Bay'!E67 -> 1.4379717
A19: Year 3 free cash flow to owners | B19: ='P&L 2-Bay'!E65 -> -137029.69 | C19: ='P&L 3-Bay'!E65 -> -35599.842 | D19: ='P&L 4-Bay'!E65 -> 58464.45
A20: 5-year cumulative free cash flow | B20: ='P&L 2-Bay'!G66 -> -766928.97 | C20: ='P&L 3-Bay'!G66 -> -326708.13 | D20: ='P&L 4-Bay'!G66 -> 48143.893
A21: Cash-on-cash return, Year 3 (FCF / equity) | B21: =IF(Startup!C29=0,0,'P&L 2-Bay'!E65/Startup!C29) -> -0.82915798 | C21: =IF(Startup!D29=0,0,'P&L 3-Bay'!E65/Startup!D29) -> -0.18156793 | D21: =IF(Startup!E29=0,0,'P&L 4-Bay'!E65/Startup!E29) -> 0.25769531
A22: Year 3 education hours delivered | B22: ='P&L 2-Bay'!E12 -> 564.48 | C22: ='P&L 3-Bay'!E12 -> 846.72 | D22: ='P&L 4-Bay'!E12 -> 1128.96 | E22: ≈ students served × 1 hr each; 4 students per bay-hour
A23: Year 3 students-hours of instruction (4 per bay-hour) | B23: ='P&L 2-Bay'!E12*4 -> 2257.92 | C23: ='P&L 3-Bay'!E12*4 -> 3386.88 | D23: ='P&L 4-Bay'!E12*4 -> 4515.84
A25: Model opinion
A26: • Two bays cannot carry a kitchen, an ABC license and a GM. Fixed costs are roughly the same at 2 and 4 bays; revenue is not.
A27: • Four bays is the minimum viable footprint for the concept as described (F&B + membership + education). Three works only with a landlord TI package and a cheaper kitchen.
A28: • The education arm does not dilute margin because school blocks run 9am-3pm on weekdays, when bays would otherwise sit empty. It is paid for by the Foundation, not given away.
A29: • The biggest lever is utilization, then F&B attach. Membership pre-sales de-risk Year 1 more than any other line.

Sheet Assumptions
A1: Assumptions
A2: Blue = edit. Yellow = key lever. Years are operating years from opening day.
A4: CAPACITY & PRICING
B5: Year 1 | C5: Year 2 | D5: Year 3 | E5: Year 4 | F5: Year 5
A6: Operating days per year | B6: 360 | G6: Closed ~5 holidays
A7: Bookable hours per day | B7: 14 | G7: 9am-11pm; school blocks use 9am-3pm dead time
A8: Bay utilization (% of bookable hours sold, incl. members & education) | B8: 0.28 | C8: 0.35 | D8: 0.4 | E8: 0.42 | F8: 0.44 | G8: Secondary-metro lounges mature at 35-45%. Winter (Nov-Mar) runs 55%+, summer 20-25%.
A9: Share of used hours taken by members (not billed hourly) | B9: 0.35 | G9: Members book on dues, not hourly; keeps peak bays full of committed golfers
A10: Share of used hours taken by education programs | B10: 0.08 | C10: 0.12 | D10: 0.14 | E10: 0.15 | F10: 0.15 | G10: Foundation/school blocks, billed at the education rate below
A11: Blended public hourly bay rate | B11: 45 | G11: $55 peak / $35 off-peak; per bay, up to 4-6 players
A12: Education / school-block bay rate per hour | B12: 30 | G12: Paid by Foundation or school division contract; fills weekday daytime
A13: Annual price growth | B13: 0.03
A15: MEMBERSHIPS (see Membership Tiers sheet for blended dues)
A16: Members per bay at year end | B16: 15 | C16: 22 | D16: 26 | E16: 28 | F16: 29 | G16: Ceiling ~30 per bay before members cannot get prime slots
A17: Blended monthly dues (from Membership Tiers) | B17: ='Membership Tiers'!$F$12 -> 197.5 | G17: Formula — edit tiers on that sheet
A18: Founding memberships pre-sold before opening (count) | B18: 40 | G18: Annual prepaid; sold during construction; used as working capital
A19: Founding membership price (prepaid annual) | B19: 2400 | G19: ≈ $200/mo value for $2,400 upfront + founder perks (name on wall, locker, 2 guest passes/mo)
A21: LEAGUES, LESSONS, EVENTS, RETAIL, WELLNESS
A22: League seasons per year | B22: 3 | G22: Fall, winter, spring; 8 weeks each
A23: Teams per season per bay | B23: 6 | G23: One night/week per bay-slot
A24: Players per team | B24: 4
A25: League fee per player per season | B25: 250
A26: Lesson & fitting gross revenue per bay per year (mature) | B26: 30000 | G26: PGA/LPGA pro on 50/50 split; ~6 lesson-hrs/wk/bay at $100
A27: Pro's share of lesson revenue | B27: 0.5
A28: Corporate & private event revenue per bay per year (mature) | B28: 17500 | G28: Full buyout $350-500/hr + F&B minimums; ~2 events/mo at maturity
A29: Retail & club-fitting sales per bay per year | B29: 6000
A30: Ramp to maturity for lessons/events/retail | B30: 0.55 | C30: 0.85 | D30: 1 | E30: 1.05 | F30: 1.1
A31: Wellness suites (massage / sports pedicure) — count | B31: 0 | C31: 1 | D31: 1 | E31: 2 | F31: 2 | G31: Licensed LMT / nail tech on suite rent + 15% of service revenue; starts Year 2
A32: Suite rent + revenue share per suite per year | B32: 14400 | G32: $900/mo rent + ~$300/mo share
A34: FOOD & BEVERAGE
A35: F&B spend per used bay-hour | B35: 20 | C35: 28 | D35: 31 | E35: 32 | F35: 33 | G35: Yr1 = beer/wine license; Yr2+ = mixed beverage. 4 players × $7-8/hr each
A36: F&B spend per member per month (beyond bay-hour spend) | B36: 30
A37: F&B cost of goods (%) | B37: 0.34 | G37: Bar 22%, kitchen 32-38%; blended
A38: Retail cost of goods (%) | B38: 0.55
A39: League prizes & supplies (% of league revenue) | B39: 0.1
A41: OCCUPANCY
A42: Square feet per bay (bay + seating) | B42: 850 | G42: 16'W × 28'D bay + lounge seating
A43: Common area sf (lobby, kitchen/bar, classroom, restrooms, wellness) | B43: 1500 | G43: Classroom ~350 sf; kitchen/bar ~500 sf
A44: Base rent $/sf/yr (NNN) | B44: 17 | G44: Hampton Roads flex/retail 2026 asking $14-22
A45: NNN charges $/sf/yr | B45: 4.5
...

Sheet Startup
A1: Start-up Budget & Sources / Uses
A2: Per-bay items scale with bay count; fixed items do not. Blue = edit.
A4: Line item | B4: Unit cost | C4: 2 Bays | D4: 3 Bays | E4: 4 Bays | F4: Notes
A5: Bay count | C5: 2 | D5: 3 | E5: 4
A6: USES
A7: Simulator package per bay (launch monitor, enclosure, screen, projector, turf, PC, software) | B7: 52000 | C7: =$B7*C$5 -> 104000 | D7: =$B7*D$5 -> 156000 | E7: =$B7*E$5 -> 208000 | F7: Foresight GCQuad/GCHawk or Uneekor EYE XO2 class. Trackman iO ≈ $70k+
A8: Interior build-out $/sf (walls, electrical, HVAC, flooring, ceilings) | B8: 75 | C8: =$B8*(C$5*Assumptions!$B$42+Assumptions!$B$43) -> 240000 | D8: =$B8*(D$5*Assumptions!$B$42+Assumptions!$B$43) -> 303750 | E8: =$B8*(E$5*Assumptions!$B$42+Assumptions!$B$43) -> 367500 | F8: Second-gen retail/flex space; new hood & ADA restrooms drive this
A9: Less: landlord TI allowance $/sf | B9: -20 | C9: =$B9*(C$5*Assumptions!$B$42+Assumptions!$B$43) -> -64000 | D9: =$B9*(D$5*Assumptions!$B$42+Assumptions!$B$43) -> -81000 | E9: =$B9*(E$5*Assumptions!$B$42+Assumptions!$B$43) -> -98000 | F9: Negotiable on a 7-10 yr lease; developer relationships help here
A10: Commercial kitchen (limited menu) incl. hood & fire suppression | B10: 65000 | C10: =$B10 -> 65000 | D10: =$B10 -> 65000 | E10: =$B10 -> 65000 | F10: Required to hold any VA ABC on-premises license; sized for smash burgers, wings, flatbreads
A11: Bar build-out & draft system | B11: 28000 | C11: =$B11 -> 28000 | D11: =$B11 -> 28000 | E11: =$B11 -> 28000
A12: FF&E per bay (seating, tables, TVs, bay controls) | B12: 7500 | C12: =$B12*C$5 -> 15000 | D12: =$B12*D$5 -> 22500 | E12: =$B12*E$5 -> 30000
A13: FF&E common (lobby, lounge, patio) | B13: 22000 | C13: =$B13 -> 22000 | D13: =$B13 -> 22000 | E13: =$B13 -> 22000
A14: Classroom / education lab fit-out (screens, tablets, launch-monitor data station) | B14: 18000 | C14: =$B14 -> 18000 | D14: =$B14 -> 18000 | E14: =$B14 -> 18000 | F14: Doubles as private event room and corporate meeting room
A15: Signage, exterior, AV & sound | B15: 18000 | C15: =$B15 -> 18000 | D15: =$B15 -> 18000 | E15: =$B15 -> 18000
A16: POS, booking, access control, IT, cameras | B16: 14000 | C16: =$B16 -> 14000 | D16: =$B16 -> 14000 | E16: =$B16 -> 14000
A17: Architect, MEP, permits, legal, entity formation | B17: 32000 | C17: =$B17 -> 32000 | D17: =$B17 -> 32000 | E17: =$B17 -> 32000
A18: ABC license application, background, local fees | B18: 4500 | C18: =$B18 -> 4500 | D18: =$B18 -> 4500 | E18: =$B18 -> 4500 | F18: Verify current VA ABC fee schedule
A19: Pre-opening marketing & founding-member campaign | B19: 25000 | C19: =$B19 -> 25000 | D19: =$B19 -> 25000 | E19: =$B19 -> 25000
A20: Pre-opening payroll & training (6 weeks) | B20: 32000 | C20: =$B20 -> 32000 | D20: =$B20 -> 32000 | E20: =$B20 -> 32000
A21: Opening inventory (F&B, retail, balls, gloves) | B21: 12000 | C21: =$B21 -> 12000 | D21: =$B21 -> 12000 | E21: =$B21 -> 12000
A22: Subtotal before working capital & contingency | C22: =SUM(C7:C21) -> 565500 | D22: =SUM(D7:D21) -> 671750 | E22: =SUM(E7:E21) -> 778000
A23: Contingency (% of subtotal) | B23: 0.1 | C23: =C22*$B23 -> 56550 | D23: =D22*$B23 -> 67175 | E23: =E22*$B23 -> 77800 | F23: 10% minimum on a first location
A24: Working capital reserve (months of Year-1 cash opex) — covers the Yr1-2 ramp | B24: 6 | C24: =$B24*'P&L 2-Bay'!$C$40/12 -> 204268.36 | D24: =$B24*'P&L 3-Bay'!$C$40/12 -> 241419.99 | E24: =$B24*'P&L 4-Bay'!$C$40/12 -> 278571.63 | F24: Links to Year-1 total operating expenses on each P&L sheet
A25: TOTAL PROJECT COST | C25: =C22+C23+C24 -> 826318.36 | D25: =D22+D23+D24 -> 980344.99 | E25: =E22+E23+E24 -> 1134371.6
A27: SOURCES
A28: Founding membership pre-sales (cash, deferred revenue) | C28: =Assumptions!$B$18*Assumptions!$B$19*C$5/4 -> 48000 | D28: =Assumptions!$B$18*Assumptions!$B$19*D$5/4 -> 72000 | E28: =Assumptions!$B$18*Assumptions!$B$19*E$5/4 -> 96000 | F28: Scaled to bay count (40 founders assumes 4 bays)
A29: Owner equity | C29: =Assumptions!$B$73*C25 -> 165263.67 | D29: =Assumptions!$B$73*D25 -> 196069 | E29: =Assumptions!$B$73*E25 -> 226874.33
A30: SBA 7(a) loan (plug) | C30: =C25-C28-C29 -> 613054.69 | D30: =D25-D28-D29 -> 712276 | E30: =E25-E28-E29 -> 811497.3
A31: Annual debt service (P&I) | C31: =-PMT(Assumptions!$B$74,Assumptions!$B$75,C30) -> 100845.84 | D31: =-PMT(Assumptions!$B$74,Assumptions!$B$75,D30) -> 117167.48 | E31: =-PMT(Assumptions!$B$74,Assumptions!$B$75,E30) -> 133489.12
A32: Depreciable capex (hard costs before contingency) | C32: =C22+C23 -> 622050 | D32: =D22+D23 -> 738925 | E32: =E22+E23 -> 855800
A33: Total sq ft | C33: =C$5*Assumptions!$B$42+Assumptions!$B$43 -> 3200 | D33: =D$5*Assumptions!$B$42+Assumptions!$B$43 -> 4050 | E33: =E$5*Assumptions!$B$42+Assumptions!$B$43 -> 4900

Sheet P&L 2-Bay
A1: P&L 2-Bay — 5-Year Operating Projection
A2: All revenue and cost lines are formulas driven by Assumptions and Startup. Bay count comes from the Startup sheet.
A4: Bays | B4: =Startup!C$5 -> 2
A5: Available bay-hours / yr | B5: =$B$4*Assumptions!$B$6*Assumptions!$B$7 -> 10080
A7: ($, annual) | C7: Year 1 | D7: Year 2 | E7: Year 3 | F7: Year 4 | G7: Year 5 | H7: Driver
A8: OPERATING DRIVERS
A9: Utilization | C9: =Assumptions!$B$8 -> 0.28 | D9: =Assumptions!$C$8 -> 0.35 | E9: =Assumptions!$D$8 -> 0.4 | F9: =Assumptions!$E$8 -> 0.42 | G9: =Assumptions!$F$8 -> 0.44
A10: Used bay-hours | C10: =$B$5*C9 -> 2822.4 | D10: =$B$5*D9 -> 3528 | E10: =$B$5*E9 -> 4032 | F10: =$B$5*F9 -> 4233.6 | G10: =$B$5*G9 -> 4435.2
A11: of which: member hours | C11: =C10*Assumptions!$B$9 -> 987.84 | D11: =D10*Assumptions!$B$9 -> 1234.8 | E11: =E10*Assumptions!$B$9 -> 1411.2 | F11: =F10*Assumptions!$B$9 -> 1481.76 | G11: =G10*Assumptions!$B$9 -> 1552.32
A12: of which: education hours | C12: =C10*Assumptions!$B$10 -> 225.792 | D12: =D10*Assumptions!$C$10 -> 423.36 | E12: =E10*Assumptions!$D$10 -> 564.48 | F12: =F10*Assumptions!$E$10 -> 635.04 | G12: =G10*Assumptions!$F$10 -> 665.28
A13: of which: public paid hours | C13: =C10-C11-C12 -> 1608.768 | D13: =D10-D11-D12 -> 1869.84 | E13: =E10-E11-E12 -> 2056.32 | F13: =F10-F11-F12 -> 2116.8 | G13: =G10-G11-G12 -> 2217.6
A14: Members (year-end) | C14: =Assumptions!$B$16*$B$4 -> 30 | D14: =Assumptions!$C$16*$B$4 -> 44 | E14: =Assumptions!$D$16*$B$4 -> 52 | F14: =Assumptions!$E$16*$B$4 -> 56 | G14: =Assumptions!$F$16*$B$4 -> 58
A15: Average members during year | C15: =(Assumptions!$B$18*$B$4/4+C14)/2 -> 25 | D15: =(C14+D14)/2 -> 37 | E15: =(D14+E14)/2 -> 48 | F15: =(E14+F14)/2 -> 54 | G15: =(F14+G14)/2 -> 57 | H15: Yr1 starts with founding members
A17: REVENUE
A18: Public bay rental | C18: =C13*Assumptions!$B$11*(1+Assumptions!$B$13)^0 -> 72394.56 | D18: =D13*Assumptions!$B$11*(1+Assumptions!$B$13)^1 -> 86667.084 | E18: =E13*Assumptions!$B$11*(1+Assumptions!$B$13)^2 -> 98169.745 | F18: =F13*Assumptions!$B$11*(1+Assumptions!$B$13)^3 -> 104088.8 | G18: =G13*Assumptions!$B$11*(1+Assumptions!$B$13)^4 -> 112316.78 | H18: Paid hours × blended rate
A19: Membership dues | C19: =C15*Assumptions!$B$17*12*(1+Assumptions!$B$13)^0 -> 59250 | D19: =D15*Assumptions!$B$17*12*(1+Assumptions!$B$13)^1 -> 90320.7 | E19: =E15*Assumptions!$B$17*12*(1+Assumptions!$B$13)^2 -> 120687.98 | F19: =F15*Assumptions!$B$17*12*(1+Assumptions!$B$13)^3 -> 139847.2 | G19: =G15*Assumptions!$B$17*12*(1+Assumptions!$B$13)^4 -> 152044.99
A20: Education & school-block bay time | C20: =C12*Assumptions!$B$12*(1+Assumptions!$B$13)^0 -> 6773.76 | D20: =D12*Assumptions!$B$12*(1+Assumptions!$B$13)^1 -> 13081.824 | E20: =E12*Assumptions!$B$12*(1+Assumptions!$B$13)^2 -> 17965.705 | F20: =F12*Assumptions!$B$12*(1+Assumptions!$B$13)^3 -> 20817.761 | G20: =G12*Assumptions!$B$12*(1+Assumptions!$B$13)^4 -> 22463.355 | H20: Paid by Foundation / school contracts
A21: Leagues | C21: =Assumptions!$B$22*Assumptions!$B$23*$B$4*Assumptions!$B$24*Assumptions!$B$25*Assumptions!$B$30*(1+Assumptions!$B$13)^0 -> 19800 | D21: =Assumptions!$B$22*Assumptions!$B$23*$B$4*Assumptions!$B$24*Assumptions!$B$25*Assumptions!$C$30*(1+Assumptions!$B$13)^1 -> 31518 | E21: =Assumptions!$B$22*Assumptions!$B$23*$B$4*Assumptions!$B$24*Assumptions!$B$25*Assumptions!$D$30*(1+Assumptions!$B$13)^2 -> 38192.4 | F21: =Assumptions!$B$22*Assumptions!$B$23*$B$4*Assumptions!$B$24*Assumptions!$B$25*Assumptions!$E$30*(1+Assumptions!$B$13)^3 -> 41305.081 | G21: =Assumptions!$B$22*Assumptions!$B$23*$B$4*Assumptions!$B$24*Assumptions!$B$25*Assumptions!$F$30*(1+Assumptions!$B$13)^4 -> 44570.149
A22: Lessons & club fitting (gross) | C22: =Assumptions!$B$26*$B$4*Assumptions!$B$30*(1+Assumptions!$B$13)^0 -> 33000 | D22: =Assumptions!$B$26*$B$4*Assumptions!$C$30*(1+Assumptions!$B$13)^1 -> 52530 | E22: =Assumptions!$B$26*$B$4*Assumptions!$D$30*(1+Assumptions!$B$13)^2 -> 63654 | F22: =Assumptions!$B$26*$B$4*Assumptions!$E$30*(1+Assumptions!$B$13)^3 -> 68841.801 | G22: =Assumptions!$B$26*$B$4*Assumptions!$F$30*(1+Assumptions!$B$13)^4 -> 74283.581
A23: Corporate & private events | C23: =Assumptions!$B$28*$B$4*Assumptions!$B$30*(1+Assumptions!$B$13)^0 -> 19250 | D23: =Assumptions!$B$28*$B$4*Assumptions!$C$30*(1+Assumptions!$B$13)^1 -> 30642.5 | E23: =Assumptions!$B$28*$B$4*Assumptions!$D$30*(1+Assumptions!$B$13)^2 -> 37131.5 | F23: =Assumptions!$B$28*$B$4*Assumptions!$E$30*(1+Assumptions!$B$13)^3 -> 40157.717 | G23: =Assumptions!$B$28*$B$4*Assumptions!$F$30*(1+Assumptions!$B$13)^4 -> 43332.089
A24: Food & beverage | C24: =C10*Assumptions!$B$35+C15*Assumptions!$B$36*12*(1+Assumptions!$B$13)^0 -> 65448 | D24: =D10*Assumptions!$C$35+D15*Assumptions!$B$36*12*(1+Assumptions!$B$13)^1 -> 112503.6 | E24: =E10*Assumptions!$D$35+E15*Assumptions!$B$36*12*(1+Assumptions!$B$13)^2 -> 143324.35 | F24: =F10*Assumptions!$E$35+F15*Assumptions!$B$36*12*(1+Assumptions!$B$13)^3 -> 156717.81 | G24: =G10*Assumptions!$F$35+G15*Assumptions!$B$36*12*(1+Assumptions!$B$13)^4 -> 169457.04 | H24: Per used hour + member spend
A25: Retail | C25: =Assumptions!$B$29*$B$4*Assumptions!$B$30*(1+Assumptions!$B$13)^0 -> 6600 | D25: =Assumptions!$B$29*$B$4*Assumptions!$C$30*(1+Assumptions!$B$13)^1 -> 10506 | E25: =Assumptions!$B$29*$B$4*Assumptions!$D$30*(1+Assumptions!$B$13)^2 -> 12730.8 | F25: =Assumptions!$B$29*$B$4*Assumptions!$E$30*(1+Assumptions!$B$13)^3 -> 13768.36 | G25: =Assumptions!$B$29*$B$4*Assumptions!$F$30*(1+Assumptions!$B$13)^4 -> 14856.716
A26: Wellness suite rent & revenue share | C26: =Assumptions!$B$31*Assumptions!$B$32*(1+Assumptions!$B$13)^0 -> 0 | D26: =Assumptions!$C$31*Assumptions!$B$32*(1+Assumptions!$B$13)^1 -> 14832 | E26: =Assumptions!$D$31*Assumptions!$B$32*(1+Assumptions!$B$13)^2 -> 15276.96 | F26: =Assumptions!$E$31*Assumptions!$B$32*(1+Assumptions!$B$13)^3 -> 31470.538 | G26: =Assumptions!$F$31*Assumptions!$B$32*(1+Assumptions!$B$13)^4 -> 32414.654
A27: TOTAL REVENUE | C27: =SUM(C18:C26) -> 282516.32 | D27: =SUM(D18:D26) -> 442601.71 | E27: =SUM(E18:E26) -> 547133.45 | F27: =SUM(F18:F26) -> 617015.07 | G27: =SUM(G18:G26) -> 665739.35
A29: COST OF SALES
A30: F&B cost of goods | C30: =C24*Assumptions!$B$37 -> 22252.32 | D30: =D24*Assumptions!$B$37 -> 38251.224 | E30: =E24*Assumptions!$B$37 -> 48730.28 | F30: =F24*Assumptions!$B$37 -> 53284.056 | G30: =G24*Assumptions!$B$37 -> 57615.394
A31: Pro's share of lessons | C31: =C22*Assumptions!$B$27 -> 16500 | D31: =D22*Assumptions!$B$27 -> 26265 | E31: =E22*Assumptions!$B$27 -> 31827 | F31: =F22*Assumptions!$B$27 -> 34420.901 | G31: =G22*Assumptions!$B$27 -> 37141.791
A32: Retail COGS | C32: =C25*Assumptions!$B$38 -> 3630 | D32: =D25*Assumptions!$B$38 -> 5778.3 | E32: =E25*Assumptions!$B$38 -> 7001.94 | F32: =F25*Assumptions!$B$38 -> 7572.5981 | G32: =G25*Assumptions!$B$38 -> 8171.194
A33: League prizes & supplies | C33: =C21*Assumptions!$B$39 -> 1980 | D33: =D21*Assumptions!$B$39 -> 3151.8 | E33: =E21*Assumptions!$B$39 -> 3819.24 | F33: =F21*Assumptions!$B$39 -> 4130.5081 | G33: =G21*Assumptions!$B$39 -> 4457.0149
A34: GROSS PROFIT | C34: =C27-SUM(C30:C33) -> 238154 | D34: =D27-SUM(D30:D33) -> 369155.38 | E34: =E27-SUM(E30:E33) -> 455754.99 | F34: =F27-SUM(F30:F33) -> 517607.01 | G34: =G27-SUM(G30:G33) -> 558353.95
A35: Gross margin | C35: =IF(C27=0,0,C34/C27) -> 0.84297431 | D35: =IF(D27=0,0,D34/D27) -> 0.83405775 | E35: =IF(E27=0,0,E34/E27) -> 0.83298689 | F35: =IF(F27=0,0,F34/F27) -> 0.83888876 | G35: =IF(G27=0,0,G34/G27) -> 0.83869754
A37: OPERATING EXPENSES
A38: Rent + NNN | C38: =Startup!C$33*(Assumptions!$B$44+Assumptions!$B$45)*(1+Assumptions!$B$46)^0 -> 68800 | D38: =Startup!C$33*(Assumptions!$B$44+Assumptions!$B$45)*(1+Assumptions!$B$46)^1 -> 70864 | E38: =Startup!C$33*(Assumptions!$B$44+Assumptions!$B$45)*(1+Assumptions!$B$46)^2 -> 72989.92 | F38: =Startup!C$33*(Assumptions!$B$44+Assumptions!$B$45)*(1+Assumptions!$B$46)^3 -> 75179.618 | G38: =Startup!C$33*(Assumptions!$B$44+Assumptions!$B$45)*(1+Assumptions!$B$46)^4 -> 77435.006
A39: Payroll — salaried (GM, Director net of Foundation reimb., kitchen lead) | C39: =(Assumptions!$B$50+Assumptions!$B$51*(1-Assumptions!$B$52)+Assumptions!$B$53)*(1+Assumptions!$B$58)*(1+Assumptions!$B$59)^0 -> 155040 | D39: =(Assumptions!$B$50+Assumptions!$B$51*(1-Assumptions!$B$52)+Assumptions!$B$53)*(1+Assumptions!$B$58)*(1+Assumptions!$B$59)^1 -> 159691.2 | E39: =(Assumptions!$B$50+Assumptions!$B$51*(1-Assumptions!$B$52)+Assumptions!$B$53)*(1+Assumptions!$B$58)*(1+Assumptions!$B$59)^2 -> 164481.94 | F39: =(Assumptions!$B$50+Assumptions!$B$51*(1-Assumptions!$B$52)+Assumptions!$B$53)*(1+Assumptions!$B$58)*(1+Assumptions!$B$59)^3 -> 169416.39 | G39: =(Assumptions!$B$50+Assumptions!$B$51*(1-Assumptions!$B$52)+Assumptions!$B$53)*(1+Assumptions!$B$58)*(1+Assumptions!$B$59)^4 -> 174498.89
A40: TOTAL OPERATING EXPENSES | C40: =SUM(C38:C39)+SUM(C41:C49) -> 408536.73 | D40: =SUM(D38:D39)+SUM(D41:D49) -> 448669.61 | E40: =SUM(E38:E39)+SUM(E41:E49) -> 480996.17 | F40: =SUM(F38:F39)+SUM(F41:F49) -> 497469.61 | G40: =SUM(G38:G39)+SUM(G41:G49) -> 514952.87 | H40: Row 40 feeds Startup working capital
A41: Payroll — hourly (front desk, bay hosts, bar, kitchen) | C41: =(Assumptions!$B$55+Assumptions!$B$54*$B$4)*52*Assumptions!$B$56*(1+Assumptions!$B$58)*(1+Assumptions!$B$59)^0*Assumptions!$B$57 -> 85452.12 | D41: =(Assumptions!$B$55+Assumptions!$B$54*$B$4)*52*Assumptions!$B$56*(1+Assumptions!$B$58)*(1+Assumptions!$B$59)^1*Assumptions!$C$57 -> 105618.82 | E41: =(Assumptions!$B$55+Assumptions!$B$54*$B$4)*52*Assumptions!$B$56*(1+Assumptions!$B$58)*(1+Assumptions!$B$59)^2*Assumptions!$D$57 -> 120874.87 | F41: =(Assumptions!$B$55+Assumptions!$B$54*$B$4)*52*Assumptions!$B$56*(1+Assumptions!$B$58)*(1+Assumptions!$B$59)^3*Assumptions!$E$57 -> 124501.12 | G41: =(Assumptions!$B$55+Assumptions!$B$54*$B$4)*52*Assumptions!$B$56*(1+Assumptions!$B$58)*(1+Assumptions!$B$59)^4*Assumptions!$F$57 -> 128236.15
A42: Simulator software & licensing | C42: =Assumptions!$B$62*$B$4+Assumptions!$B$63 -> 14400 | D42: =Assumptions!$B$62*$B$4+Assumptions!$B$63 -> 14400 | E42: =Assumptions!$B$62*$B$4+Assumptions!$B$63 -> 14400 | F42: =Assumptions!$B$62*$B$4+Assumptions!$B$63 -> 14400 | G42: =Assumptions!$B$62*$B$4+Assumptions!$B$63 -> 14400
A43: Utilities | C43: =Startup!C$33*Assumptions!$B$47*(1+Assumptions!$B$46)^0 -> 10400 | D43: =Startup!C$33*Assumptions!$B$47*(1+Assumptions!$B$46)^1 -> 10712 | E43: =Startup!C$33*Assumptions!$B$47*(1+Assumptions!$B$46)^2 -> 11033.36 | F43: =Startup!C$33*Assumptions!$B$47*(1+Assumptions!$B$46)^3 -> 11364.361 | G43: =Startup!C$33*Assumptions!$B$47*(1+Assumptions!$B$46)^4 -> 11705.292
A44: Insurance | C44: =(Assumptions!$B$64+Assumptions!$B$65*$B$4)*(1+Assumptions!$B$46)^0 -> 17000 | D44: =(Assumptions!$B$64+Assumptions!$B$65*$B$4)*(1+Assumptions!$B$46)^1 -> 17510 | E44: =(Assumptions!$B$64+Assumptions!$B$65*$B$4)*(1+Assumptions!$B$46)^2 -> 18035.3 | F44: =(Assumptions!$B$64+Assumptions!$B$65*$B$4)*(1+Assumptions!$B$46)^3 -> 18576.359 | G44: =(Assumptions!$B$64+Assumptions!$B$65*$B$4)*(1+Assumptions!$B$46)^4 -> 19133.65
A45: Marketing | C45: =C27*Assumptions!$B$66 -> 19776.142 | D45: =D27*Assumptions!$C$66 -> 22130.085 | E45: =E27*Assumptions!$D$66 -> 24621.005 | F45: =F27*Assumptions!$E$66 -> 24680.603 | G45: =G27*Assumptions!$F$66 -> 26629.574
...

Sheet P&L 3-Bay
A1: P&L 3-Bay — 5-Year Operating Projection
A2: All revenue and cost lines are formulas driven by Assumptions and Startup. Bay count comes from the Startup sheet.
A4: Bays | B4: =Startup!D$5 -> 3
A5: Available bay-hours / yr | B5: =$B$4*Assumptions!$B$6*Assumptions!$B$7 -> 15120
A7: ($, annual) | C7: Year 1 | D7: Year 2 | E7: Year 3 | F7: Year 4 | G7: Year 5 | H7: Driver
A8: OPERATING DRIVERS
A9: Utilization | C9: =Assumptions!$B$8 -> 0.28 | D9: =Assumptions!$C$8 -> 0.35 | E9: =Assumptions!$D$8 -> 0.4 | F9: =Assumptions!$E$8 -> 0.42 | G9: =Assumptions!$F$8 -> 0.44
A10: Used bay-hours | C10: =$B$5*C9 -> 4233.6 | D10: =$B$5*D9 -> 5292 | E10: =$B$5*E9 -> 6048 | F10: =$B$5*F9 -> 6350.4 | G10: =$B$5*G9 -> 6652.8
A11: of which: member hours | C11: =C10*Assumptions!$B$9 -> 1481.76 | D11: =D10*Assumptions!$B$9 -> 1852.2 | E11: =E10*Assumptions!$B$9 -> 2116.8 | F11: =F10*Assumptions!$B$9 -> 2222.64 | G11: =G10*Assumptions!$B$9 -> 2328.48
A12: of which: education hours | C12: =C10*Assumptions!$B$10 -> 338.688 | D12: =D10*Assumptions!$C$10 -> 635.04 | E12: =E10*Assumptions!$D$10 -> 846.72 | F12: =F10*Assumptions!$E$10 -> 952.56 | G12: =G10*Assumptions!$F$10 -> 997.92
A13: of which: public paid hours | C13: =C10-C11-C12 -> 2413.152 | D13: =D10-D11-D12 -> 2804.76 | E13: =E10-E11-E12 -> 3084.48 | F13: =F10-F11-F12 -> 3175.2 | G13: =G10-G11-G12 -> 3326.4
A14: Members (year-end) | C14: =Assumptions!$B$16*$B$4 -> 45 | D14: =Assumptions!$C$16*$B$4 -> 66 | E14: =Assumptions!$D$16*$B$4 -> 78 | F14: =Assumptions!$E$16*$B$4 -> 84 | G14: =Assumptions!$F$16*$B$4 -> 87
A15: Average members during year | C15: =(Assumptions!$B$18*$B$4/4+C14)/2 -> 37.5 | D15: =(C14+D14)/2 -> 55.5 | E15: =(D14+E14)/2 -> 72 | F15: =(E14+F14)/2 -> 81 | G15: =(F14+G14)/2 -> 85.5 | H15: Yr1 starts with founding members
A17: REVENUE
A18: Public bay rental | C18: =C13*Assumptions!$B$11*(1+Assumptions!$B$13)^0 -> 108591.84 | D18: =D13*Assumptions!$B$11*(1+Assumptions!$B$13)^1 -> 130000.63 | E18: =E13*Assumptions!$B$11*(1+Assumptions!$B$13)^2 -> 147254.62 | F18: =F13*Assumptions!$B$11*(1+Assumptions!$B$13)^3 -> 156133.2 | G18: =G13*Assumptions!$B$11*(1+Assumptions!$B$13)^4 -> 168475.16 | H18: Paid hours × blended rate
A19: Membership dues | C19: =C15*Assumptions!$B$17*12*(1+Assumptions!$B$13)^0 -> 88875 | D19: =D15*Assumptions!$B$17*12*(1+Assumptions!$B$13)^1 -> 135481.05 | E19: =E15*Assumptions!$B$17*12*(1+Assumptions!$B$13)^2 -> 181031.98 | F19: =F15*Assumptions!$B$17*12*(1+Assumptions!$B$13)^3 -> 209770.8 | G19: =G15*Assumptions!$B$17*12*(1+Assumptions!$B$13)^4 -> 228067.48
A20: Education & school-block bay time | C20: =C12*Assumptions!$B$12*(1+Assumptions!$B$13)^0 -> 10160.64 | D20: =D12*Assumptions!$B$12*(1+Assumptions!$B$13)^1 -> 19622.736 | E20: =E12*Assumptions!$B$12*(1+Assumptions!$B$13)^2 -> 26948.557 | F20: =F12*Assumptions!$B$12*(1+Assumptions!$B$13)^3 -> 31226.641 | G20: =G12*Assumptions!$B$12*(1+Assumptions!$B$13)^4 -> 33695.033 | H20: Paid by Foundation / school contracts
A21: Leagues | C21: =Assumptions!$B$22*Assumptions!$B$23*$B$4*Assumptions!$B$24*Assumptions!$B$25*Assumptions!$B$30*(1+Assumptions!$B$13)^0 -> 29700 | D21: =Assumptions!$B$22*Assumptions!$B$23*$B$4*Assumptions!$B$24*Assumptions!$B$25*Assumptions!$C$30*(1+Assumptions!$B$13)^1 -> 47277 | E21: =Assumptions!$B$22*Assumptions!$B$23*$B$4*Assumptions!$B$24*Assumptions!$B$25*Assumptions!$D$30*(1+Assumptions!$B$13)^2 -> 57288.6 | F21: =Assumptions!$B$22*Assumptions!$B$23*$B$4*Assumptions!$B$24*Assumptions!$B$25*Assumptions!$E$30*(1+Assumptions!$B$13)^3 -> 61957.621 | G21: =Assumptions!$B$22*Assumptions!$B$23*$B$4*Assumptions!$B$24*Assumptions!$B$25*Assumptions!$F$30*(1+Assumptions!$B$13)^4 -> 66855.223
A22: Lessons & club fitting (gross) | C22: =Assumptions!$B$26*$B$4*Assumptions!$B$30*(1+Assumptions!$B$13)^0 -> 49500 | D22: =Assumptions!$B$26*$B$4*Assumptions!$C$30*(1+Assumptions!$B$13)^1 -> 78795 | E22: =Assumptions!$B$26*$B$4*Assumptions!$D$30*(1+Assumptions!$B$13)^2 -> 95481 | F22: =Assumptions!$B$26*$B$4*Assumptions!$E$30*(1+Assumptions!$B$13)^3 -> 103262.7 | G22: =Assumptions!$B$26*$B$4*Assumptions!$F$30*(1+Assumptions!$B$13)^4 -> 111425.37
A23: Corporate & private events | C23: =Assumptions!$B$28*$B$4*Assumptions!$B$30*(1+Assumptions!$B$13)^0 -> 28875 | D23: =Assumptions!$B$28*$B$4*Assumptions!$C$30*(1+Assumptions!$B$13)^1 -> 45963.75 | E23: =Assumptions!$B$28*$B$4*Assumptions!$D$30*(1+Assumptions!$B$13)^2 -> 55697.25 | F23: =Assumptions!$B$28*$B$4*Assumptions!$E$30*(1+Assumptions!$B$13)^3 -> 60236.576 | G23: =Assumptions!$B$28*$B$4*Assumptions!$F$30*(1+Assumptions!$B$13)^4 -> 64998.134
A24: Food & beverage | C24: =C10*Assumptions!$B$35+C15*Assumptions!$B$36*12*(1+Assumptions!$B$13)^0 -> 98172 | D24: =D10*Assumptions!$C$35+D15*Assumptions!$B$36*12*(1+Assumptions!$B$13)^1 -> 168755.4 | E24: =E10*Assumptions!$D$35+E15*Assumptions!$B$36*12*(1+Assumptions!$B$13)^2 -> 214986.53 | F24: =F10*Assumptions!$E$35+F15*Assumptions!$B$36*12*(1+Assumptions!$B$13)^3 -> 235076.72 | G24: =G10*Assumptions!$F$35+G15*Assumptions!$B$36*12*(1+Assumptions!$B$13)^4 -> 254185.56 | H24: Per used hour + member spend
A25: Retail | C25: =Assumptions!$B$29*$B$4*Assumptions!$B$30*(1+Assumptions!$B$13)^0 -> 9900 | D25: =Assumptions!$B$29*$B$4*Assumptions!$C$30*(1+Assumptions!$B$13)^1 -> 15759 | E25: =Assumptions!$B$29*$B$4*Assumptions!$D$30*(1+Assumptions!$B$13)^2 -> 19096.2 | F25: =Assumptions!$B$29*$B$4*Assumptions!$E$30*(1+Assumptions!$B$13)^3 -> 20652.54 | G25: =Assumptions!$B$29*$B$4*Assumptions!$F$30*(1+Assumptions!$B$13)^4 -> 22285.074
A26: Wellness suite rent & revenue share | C26: =Assumptions!$B$31*Assumptions!$B$32*(1+Assumptions!$B$13)^0 -> 0 | D26: =Assumptions!$C$31*Assumptions!$B$32*(1+Assumptions!$B$13)^1 -> 14832 | E26: =Assumptions!$D$31*Assumptions!$B$32*(1+Assumptions!$B$13)^2 -> 15276.96 | F26: =Assumptions!$E$31*Assumptions!$B$32*(1+Assumptions!$B$13)^3 -> 31470.538 | G26: =Assumptions!$F$31*Assumptions!$B$32*(1+Assumptions!$B$13)^4 -> 32414.654
A27: TOTAL REVENUE | C27: =SUM(C18:C26) -> 423774.48 | D27: =SUM(D18:D26) -> 656486.56 | E27: =SUM(E18:E26) -> 813061.69 | F27: =SUM(F18:F26) -> 909787.34 | G27: =SUM(G18:G26) -> 982401.69
A29: COST OF SALES
A30: F&B cost of goods | C30: =C24*Assumptions!$B$37 -> 33378.48 | D30: =D24*Assumptions!$B$37 -> 57376.836 | E30: =E24*Assumptions!$B$37 -> 73095.42 | F30: =F24*Assumptions!$B$37 -> 79926.085 | G30: =G24*Assumptions!$B$37 -> 86423.091
A31: Pro's share of lessons | C31: =C22*Assumptions!$B$27 -> 24750 | D31: =D22*Assumptions!$B$27 -> 39397.5 | E31: =E22*Assumptions!$B$27 -> 47740.5 | F31: =F22*Assumptions!$B$27 -> 51631.351 | G31: =G22*Assumptions!$B$27 -> 55712.686
A32: Retail COGS | C32: =C25*Assumptions!$B$38 -> 5445 | D32: =D25*Assumptions!$B$38 -> 8667.45 | E32: =E25*Assumptions!$B$38 -> 10502.91 | F32: =F25*Assumptions!$B$38 -> 11358.897 | G32: =G25*Assumptions!$B$38 -> 12256.791
A33: League prizes & supplies | C33: =C21*Assumptions!$B$39 -> 2970 | D33: =D21*Assumptions!$B$39 -> 4727.7 | E33: =E21*Assumptions!$B$39 -> 5728.86 | F33: =F21*Assumptions!$B$39 -> 6195.7621 | G33: =G21*Assumptions!$B$39 -> 6685.5223
A34: GROSS PROFIT | C34: =C27-SUM(C30:C33) -> 357231 | D34: =D27-SUM(D30:D33) -> 546317.08 | E34: =E27-SUM(E30:E33) -> 675994 | F34: =F27-SUM(F30:F33) -> 760675.25 | G34: =G27-SUM(G30:G33) -> 821323.6
A35: Gross margin | C35: =IF(C27=0,0,C34/C27) -> 0.84297431 | D35: =IF(D27=0,0,D34/D27) -> 0.83218318 | E35: =IF(E27=0,0,E34/E27) -> 0.83141785 | F35: =IF(F27=0,0,F34/F27) -> 0.83610225 | G35: =IF(G27=0,0,G34/G27) -> 0.83603643
A37: OPERATING EXPENSES
A38: Rent + NNN | C38: =Startup!D$33*(Assumptions!$B$44+Assumptions!$B$45)*(1+Assumptions!$B$46)^0 -> 87075 | D38: =Startup!D$33*(Assumptions!$B$44+Assumptions!$B$45)*(1+Assumptions!$B$46)^1 -> 89687.25 | E38: =Startup!D$33*(Assumptions!$B$44+Assumptions!$B$45)*(1+Assumptions!$B$46)^2 -> 92377.867 | F38: =Startup!D$33*(Assumptions!$B$44+Assumptions!$B$45)*(1+Assumptions!$B$46)^3 -> 95149.204 | G38: =Startup!D$33*(Assumptions!$B$44+Assumptions!$B$45)*(1+Assumptions!$B$46)^4 -> 98003.68
A39: Payroll — salaried (GM, Director net of Foundation reimb., kitchen lead) | C39: =(Assumptions!$B$50+Assumptions!$B$51*(1-Assumptions!$B$52)+Assumptions!$B$53)*(1+Assumptions!$B$58)*(1+Assumptions!$B$59)^0 -> 155040 | D39: =(Assumptions!$B$50+Assumptions!$B$51*(1-Assumptions!$B$52)+Assumptions!$B$53)*(1+Assumptions!$B$58)*(1+Assumptions!$B$59)^1 -> 159691.2 | E39: =(Assumptions!$B$50+Assumptions!$B$51*(1-Assumptions!$B$52)+Assumptions!$B$53)*(1+Assumptions!$B$58)*(1+Assumptions!$B$59)^2 -> 164481.94 | F39: =(Assumptions!$B$50+Assumptions!$B$51*(1-Assumptions!$B$52)+Assumptions!$B$53)*(1+Assumptions!$B$58)*(1+Assumptions!$B$59)^3 -> 169416.39 | G39: =(Assumptions!$B$50+Assumptions!$B$51*(1-Assumptions!$B$52)+Assumptions!$B$53)*(1+Assumptions!$B$58)*(1+Assumptions!$B$59)^4 -> 174498.89
A40: TOTAL OPERATING EXPENSES | C40: =SUM(C38:C39)+SUM(C41:C49) -> 482839.99 | D40: =SUM(D38:D39)+SUM(D41:D49) -> 535600.8 | E40: =SUM(E38:E39)+SUM(E41:E49) -> 578165.13 | F40: =SUM(F38:F39)+SUM(F41:F49) -> 597943.86 | G40: =SUM(G38:G39)+SUM(G41:G49) -> 619828.93 | H40: Row 40 feeds Startup working capital
A41: Payroll — hourly (front desk, bay hosts, bar, kitchen) | C41: =(Assumptions!$B$55+Assumptions!$B$54*$B$4)*52*Assumptions!$B$56*(1+Assumptions!$B$58)*(1+Assumptions!$B$59)^0*Assumptions!$B$57 -> 114395.58 | D41: =(Assumptions!$B$55+Assumptions!$B$54*$B$4)*52*Assumptions!$B$56*(1+Assumptions!$B$58)*(1+Assumptions!$B$59)^1*Assumptions!$C$57 -> 141392.94 | E41: =(Assumptions!$B$55+Assumptions!$B$54*$B$4)*52*Assumptions!$B$56*(1+Assumptions!$B$58)*(1+Assumptions!$B$59)^2*Assumptions!$D$57 -> 161816.36 | F41: =(Assumptions!$B$55+Assumptions!$B$54*$B$4)*52*Assumptions!$B$56*(1+Assumptions!$B$58)*(1+Assumptions!$B$59)^3*Assumptions!$E$57 -> 166670.85 | G41: =(Assumptions!$B$55+Assumptions!$B$54*$B$4)*52*Assumptions!$B$56*(1+Assumptions!$B$58)*(1+Assumptions!$B$59)^4*Assumptions!$F$57 -> 171670.98
A42: Simulator software & licensing | C42: =Assumptions!$B$62*$B$4+Assumptions!$B$63 -> 18000 | D42: =Assumptions!$B$62*$B$4+Assumptions!$B$63 -> 18000 | E42: =Assumptions!$B$62*$B$4+Assumptions!$B$63 -> 18000 | F42: =Assumptions!$B$62*$B$4+Assumptions!$B$63 -> 18000 | G42: =Assumptions!$B$62*$B$4+Assumptions!$B$63 -> 18000
A43: Utilities | C43: =Startup!D$33*Assumptions!$B$47*(1+Assumptions!$B$46)^0 -> 13162.5 | D43: =Startup!D$33*Assumptions!$B$47*(1+Assumptions!$B$46)^1 -> 13557.375 | E43: =Startup!D$33*Assumptions!$B$47*(1+Assumptions!$B$46)^2 -> 13964.096 | F43: =Startup!D$33*Assumptions!$B$47*(1+Assumptions!$B$46)^3 -> 14383.019 | G43: =Startup!D$33*Assumptions!$B$47*(1+Assumptions!$B$46)^4 -> 14814.51
A44: Insurance | C44: =(Assumptions!$B$64+Assumptions!$B$65*$B$4)*(1+Assumptions!$B$46)^0 -> 19500 | D44: =(Assumptions!$B$64+Assumptions!$B$65*$B$4)*(1+Assumptions!$B$46)^1 -> 20085 | E44: =(Assumptions!$B$64+Assumptions!$B$65*$B$4)*(1+Assumptions!$B$46)^2 -> 20687.55 | F44: =(Assumptions!$B$64+Assumptions!$B$65*$B$4)*(1+Assumptions!$B$46)^3 -> 21308.177 | G44: =(Assumptions!$B$64+Assumptions!$B$65*$B$4)*(1+Assumptions!$B$46)^4 -> 21947.422
A45: Marketing | C45: =C27*Assumptions!$B$66 -> 29664.214 | D45: =D27*Assumptions!$C$66 -> 32824.328 | E45: =E27*Assumptions!$D$66 -> 36587.776 | F45: =F27*Assumptions!$E$66 -> 36391.494 | G45: =G27*Assumptions!$F$66 -> 39296.068
...

Sheet P&L 4-Bay
A1: P&L 4-Bay — 5-Year Operating Projection
A2: All revenue and cost lines are formulas driven by Assumptions and Startup. Bay count comes from the Startup sheet.
A4: Bays | B4: =Startup!E$5 -> 4
A5: Available bay-hours / yr | B5: =$B$4*Assumptions!$B$6*Assumptions!$B$7 -> 20160
A7: ($, annual) | C7: Year 1 | D7: Year 2 | E7: Year 3 | F7: Year 4 | G7: Year 5 | H7: Driver
A8: OPERATING DRIVERS
A9: Utilization | C9: =Assumptions!$B$8 -> 0.28 | D9: =Assumptions!$C$8 -> 0.35 | E9: =Assumptions!$D$8 -> 0.4 | F9: =Assumptions!$E$8 -> 0.42 | G9: =Assumptions!$F$8 -> 0.44
A10: Used bay-hours | C10: =$B$5*C9 -> 5644.8 | D10: =$B$5*D9 -> 7056 | E10: =$B$5*E9 -> 8064 | F10: =$B$5*F9 -> 8467.2 | G10: =$B$5*G9 -> 8870.4
A11: of which: member hours | C11: =C10*Assumptions!$B$9 -> 1975.68 | D11: =D10*Assumptions!$B$9 -> 2469.6 | E11: =E10*Assumptions!$B$9 -> 2822.4 | F11: =F10*Assumptions!$B$9 -> 2963.52 | G11: =G10*Assumptions!$B$9 -> 3104.64
A12: of which: education hours | C12: =C10*Assumptions!$B$10 -> 451.584 | D12: =D10*Assumptions!$C$10 -> 846.72 | E12: =E10*Assumptions!$D$10 -> 1128.96 | F12: =F10*Assumptions!$E$10 -> 1270.08 | G12: =G10*Assumptions!$F$10 -> 1330.56
A13: of which: public paid hours | C13: =C10-C11-C12 -> 3217.536 | D13: =D10-D11-D12 -> 3739.68 | E13: =E10-E11-E12 -> 4112.64 | F13: =F10-F11-F12 -> 4233.6 | G13: =G10-G11-G12 -> 4435.2
A14: Members (year-end) | C14: =Assumptions!$B$16*$B$4 -> 60 | D14: =Assumptions!$C$16*$B$4 -> 88 | E14: =Assumptions!$D$16*$B$4 -> 104 | F14: =Assumptions!$E$16*$B$4 -> 112 | G14: =Assumptions!$F$16*$B$4 -> 116
A15: Average members during year | C15: =(Assumptions!$B$18*$B$4/4+C14)/2 -> 50 | D15: =(C14+D14)/2 -> 74 | E15: =(D14+E14)/2 -> 96 | F15: =(E14+F14)/2 -> 108 | G15: =(F14+G14)/2 -> 114 | H15: Yr1 starts with founding members
A17: REVENUE
A18: Public bay rental | C18: =C13*Assumptions!$B$11*(1+Assumptions!$B$13)^0 -> 144789.12 | D18: =D13*Assumptions!$B$11*(1+Assumptions!$B$13)^1 -> 173334.17 | E18: =E13*Assumptions!$B$11*(1+Assumptions!$B$13)^2 -> 196339.49 | F18: =F13*Assumptions!$B$11*(1+Assumptions!$B$13)^3 -> 208177.61 | G18: =G13*Assumptions!$B$11*(1+Assumptions!$B$13)^4 -> 224633.55 | H18: Paid hours × blended rate
A19: Membership dues | C19: =C15*Assumptions!$B$17*12*(1+Assumptions!$B$13)^0 -> 118500 | D19: =D15*Assumptions!$B$17*12*(1+Assumptions!$B$13)^1 -> 180641.4 | E19: =E15*Assumptions!$B$17*12*(1+Assumptions!$B$13)^2 -> 241375.97 | F19: =F15*Assumptions!$B$17*12*(1+Assumptions!$B$13)^3 -> 279694.4 | G19: =G15*Assumptions!$B$17*12*(1+Assumptions!$B$13)^4 -> 304089.97
A20: Education & school-block bay time | C20: =C12*Assumptions!$B$12*(1+Assumptions!$B$13)^0 -> 13547.52 | D20: =D12*Assumptions!$B$12*(1+Assumptions!$B$13)^1 -> 26163.648 | E20: =E12*Assumptions!$B$12*(1+Assumptions!$B$13)^2 -> 35931.41 | F20: =F12*Assumptions!$B$12*(1+Assumptions!$B$13)^3 -> 41635.521 | G20: =G12*Assumptions!$B$12*(1+Assumptions!$B$13)^4 -> 44926.71 | H20: Paid by Foundation / school contracts
A21: Leagues | C21: =Assumptions!$B$22*Assumptions!$B$23*$B$4*Assumptions!$B$24*Assumptions!$B$25*Assumptions!$B$30*(1+Assumptions!$B$13)^0 -> 39600 | D21: =Assumptions!$B$22*Assumptions!$B$23*$B$4*Assumptions!$B$24*Assumptions!$B$25*Assumptions!$C$30*(1+Assumptions!$B$13)^1 -> 63036 | E21: =Assumptions!$B$22*Assumptions!$B$23*$B$4*Assumptions!$B$24*Assumptions!$B$25*Assumptions!$D$30*(1+Assumptions!$B$13)^2 -> 76384.8 | F21: =Assumptions!$B$22*Assumptions!$B$23*$B$4*Assumptions!$B$24*Assumptions!$B$25*Assumptions!$E$30*(1+Assumptions!$B$13)^3 -> 82610.161 | G21: =Assumptions!$B$22*Assumptions!$B$23*$B$4*Assumptions!$B$24*Assumptions!$B$25*Assumptions!$F$30*(1+Assumptions!$B$13)^4 -> 89140.298
A22: Lessons & club fitting (gross) | C22: =Assumptions!$B$26*$B$4*Assumptions!$B$30*(1+Assumptions!$B$13)^0 -> 66000 | D22: =Assumptions!$B$26*$B$4*Assumptions!$C$30*(1+Assumptions!$B$13)^1 -> 105060 | E22: =Assumptions!$B$26*$B$4*Assumptions!$D$30*(1+Assumptions!$B$13)^2 -> 127308 | F22: =Assumptions!$B$26*$B$4*Assumptions!$E$30*(1+Assumptions!$B$13)^3 -> 137683.6 | G22: =Assumptions!$B$26*$B$4*Assumptions!$F$30*(1+Assumptions!$B$13)^4 -> 148567.16
A23: Corporate & private events | C23: =Assumptions!$B$28*$B$4*Assumptions!$B$30*(1+Assumptions!$B$13)^0 -> 38500 | D23: =Assumptions!$B$28*$B$4*Assumptions!$C$30*(1+Assumptions!$B$13)^1 -> 61285 | E23: =Assumptions!$B$28*$B$4*Assumptions!$D$30*(1+Assumptions!$B$13)^2 -> 74263 | F23: =Assumptions!$B$28*$B$4*Assumptions!$E$30*(1+Assumptions!$B$13)^3 -> 80315.435 | G23: =Assumptions!$B$28*$B$4*Assumptions!$F$30*(1+Assumptions!$B$13)^4 -> 86664.178
A24: Food & beverage | C24: =C10*Assumptions!$B$35+C15*Assumptions!$B$36*12*(1+Assumptions!$B$13)^0 -> 130896 | D24: =D10*Assumptions!$C$35+D15*Assumptions!$B$36*12*(1+Assumptions!$B$13)^1 -> 225007.2 | E24: =E10*Assumptions!$D$35+E15*Assumptions!$B$36*12*(1+Assumptions!$B$13)^2 -> 286648.7 | F24: =F10*Assumptions!$E$35+F15*Assumptions!$B$36*12*(1+Assumptions!$B$13)^3 -> 313435.63 | G24: =G10*Assumptions!$F$35+G15*Assumptions!$B$36*12*(1+Assumptions!$B$13)^4 -> 338914.08 | H24: Per used hour + member spend
A25: Retail | C25: =Assumptions!$B$29*$B$4*Assumptions!$B$30*(1+Assumptions!$B$13)^0 -> 13200 | D25: =Assumptions!$B$29*$B$4*Assumptions!$C$30*(1+Assumptions!$B$13)^1 -> 21012 | E25: =Assumptions!$B$29*$B$4*Assumptions!$D$30*(1+Assumptions!$B$13)^2 -> 25461.6 | F25: =Assumptions!$B$29*$B$4*Assumptions!$E$30*(1+Assumptions!$B$13)^3 -> 27536.72 | G25: =Assumptions!$B$29*$B$4*Assumptions!$F$30*(1+Assumptions!$B$13)^4 -> 29713.433
A26: Wellness suite rent & revenue share | C26: =Assumptions!$B$31*Assumptions!$B$32*(1+Assumptions!$B$13)^0 -> 0 | D26: =Assumptions!$C$31*Assumptions!$B$32*(1+Assumptions!$B$13)^1 -> 14832 | E26: =Assumptions!$D$31*Assumptions!$B$32*(1+Assumptions!$B$13)^2 -> 15276.96 | F26: =Assumptions!$E$31*Assumptions!$B$32*(1+Assumptions!$B$13)^3 -> 31470.538 | G26: =Assumptions!$F$31*Assumptions!$B$32*(1+Assumptions!$B$13)^4 -> 32414.654
A27: TOTAL REVENUE | C27: =SUM(C18:C26) -> 565032.64 | D27: =SUM(D18:D26) -> 870371.42 | E27: =SUM(E18:E26) -> 1078989.9 | F27: =SUM(F18:F26) -> 1202559.6 | G27: =SUM(G18:G26) -> 1299064
A29: COST OF SALES
A30: F&B cost of goods | C30: =C24*Assumptions!$B$37 -> 44504.64 | D30: =D24*Assumptions!$B$37 -> 76502.448 | E30: =E24*Assumptions!$B$37 -> 97460.559 | F30: =F24*Assumptions!$B$37 -> 106568.11 | G30: =G24*Assumptions!$B$37 -> 115230.79
A31: Pro's share of lessons | C31: =C22*Assumptions!$B$27 -> 33000 | D31: =D22*Assumptions!$B$27 -> 52530 | E31: =E22*Assumptions!$B$27 -> 63654 | F31: =F22*Assumptions!$B$27 -> 68841.801 | G31: =G22*Assumptions!$B$27 -> 74283.581
A32: Retail COGS | C32: =C25*Assumptions!$B$38 -> 7260 | D32: =D25*Assumptions!$B$38 -> 11556.6 | E32: =E25*Assumptions!$B$38 -> 14003.88 | F32: =F25*Assumptions!$B$38 -> 15145.196 | G32: =G25*Assumptions!$B$38 -> 16342.388
A33: League prizes & supplies | C33: =C21*Assumptions!$B$39 -> 3960 | D33: =D21*Assumptions!$B$39 -> 6303.6 | E33: =E21*Assumptions!$B$39 -> 7638.48 | F33: =F21*Assumptions!$B$39 -> 8261.0161 | G33: =G21*Assumptions!$B$39 -> 8914.0298
A34: GROSS PROFIT | C34: =C27-SUM(C30:C33) -> 476308 | D34: =D27-SUM(D30:D33) -> 723478.77 | E34: =E27-SUM(E30:E33) -> 896233.01 | F34: =F27-SUM(F30:F33) -> 1003743.5 | G34: =G27-SUM(G30:G33) -> 1084293.3
A35: Gross margin | C35: =IF(C27=0,0,C34/C27) -> 0.84297431 | D35: =IF(D27=0,0,D34/D27) -> 0.83122993 | E35: =IF(E27=0,0,E34/E27) -> 0.83062222 | F35: =IF(F27=0,0,F34/F27) -> 0.83467254 | G35: =IF(G27=0,0,G34/G27) -> 0.83467267
A37: OPERATING EXPENSES
A38: Rent + NNN | C38: =Startup!E$33*(Assumptions!$B$44+Assumptions!$B$45)*(1+Assumptions!$B$46)^0 -> 105350 | D38: =Startup!E$33*(Assumptions!$B$44+Assumptions!$B$45)*(1+Assumptions!$B$46)^1 -> 108510.5 | E38: =Startup!E$33*(Assumptions!$B$44+Assumptions!$B$45)*(1+Assumptions!$B$46)^2 -> 111765.82 | F38: =Startup!E$33*(Assumptions!$B$44+Assumptions!$B$45)*(1+Assumptions!$B$46)^3 -> 115118.79 | G38: =Startup!E$33*(Assumptions!$B$44+Assumptions!$B$45)*(1+Assumptions!$B$46)^4 -> 118572.35
A39: Payroll — salaried (GM, Director net of Foundation reimb., kitchen lead) | C39: =(Assumptions!$B$50+Assumptions!$B$51*(1-Assumptions!$B$52)+Assumptions!$B$53)*(1+Assumptions!$B$58)*(1+Assumptions!$B$59)^0 -> 155040 | D39: =(Assumptions!$B$50+Assumptions!$B$51*(1-Assumptions!$B$52)+Assumptions!$B$53)*(1+Assumptions!$B$58)*(1+Assumptions!$B$59)^1 -> 159691.2 | E39: =(Assumptions!$B$50+Assumptions!$B$51*(1-Assumptions!$B$52)+Assumptions!$B$53)*(1+Assumptions!$B$58)*(1+Assumptions!$B$59)^2 -> 164481.94 | F39: =(Assumptions!$B$50+Assumptions!$B$51*(1-Assumptions!$B$52)+Assumptions!$B$53)*(1+Assumptions!$B$58)*(1+Assumptions!$B$59)^3 -> 169416.39 | G39: =(Assumptions!$B$50+Assumptions!$B$51*(1-Assumptions!$B$52)+Assumptions!$B$53)*(1+Assumptions!$B$58)*(1+Assumptions!$B$59)^4 -> 174498.89
A40: TOTAL OPERATING EXPENSES | C40: =SUM(C38:C39)+SUM(C41:C49) -> 557143.25 | D40: =SUM(D38:D39)+SUM(D41:D49) -> 622531.99 | E40: =SUM(E38:E39)+SUM(E41:E49) -> 675334.09 | F40: =SUM(F38:F39)+SUM(F41:F49) -> 698418.11 | G40: =SUM(G38:G39)+SUM(G41:G49) -> 724704.99 | H40: Row 40 feeds Startup working capital
A41: Payroll — hourly (front desk, bay hosts, bar, kitchen) | C41: =(Assumptions!$B$55+Assumptions!$B$54*$B$4)*52*Assumptions!$B$56*(1+Assumptions!$B$58)*(1+Assumptions!$B$59)^0*Assumptions!$B$57 -> 143339.04 | D41: =(Assumptions!$B$55+Assumptions!$B$54*$B$4)*52*Assumptions!$B$56*(1+Assumptions!$B$58)*(1+Assumptions!$B$59)^1*Assumptions!$C$57 -> 177167.05 | E41: =(Assumptions!$B$55+Assumptions!$B$54*$B$4)*52*Assumptions!$B$56*(1+Assumptions!$B$58)*(1+Assumptions!$B$59)^2*Assumptions!$D$57 -> 202757.85 | F41: =(Assumptions!$B$55+Assumptions!$B$54*$B$4)*52*Assumptions!$B$56*(1+Assumptions!$B$58)*(1+Assumptions!$B$59)^3*Assumptions!$E$57 -> 208840.59 | G41: =(Assumptions!$B$55+Assumptions!$B$54*$B$4)*52*Assumptions!$B$56*(1+Assumptions!$B$58)*(1+Assumptions!$B$59)^4*Assumptions!$F$57 -> 215105.8
A42: Simulator software & licensing | C42: =Assumptions!$B$62*$B$4+Assumptions!$B$63 -> 21600 | D42: =Assumptions!$B$62*$B$4+Assumptions!$B$63 -> 21600 | E42: =Assumptions!$B$62*$B$4+Assumptions!$B$63 -> 21600 | F42: =Assumptions!$B$62*$B$4+Assumptions!$B$63 -> 21600 | G42: =Assumptions!$B$62*$B$4+Assumptions!$B$63 -> 21600
A43: Utilities | C43: =Startup!E$33*Assumptions!$B$47*(1+Assumptions!$B$46)^0 -> 15925 | D43: =Startup!E$33*Assumptions!$B$47*(1+Assumptions!$B$46)^1 -> 16402.75 | E43: =Startup!E$33*Assumptions!$B$47*(1+Assumptions!$B$46)^2 -> 16894.833 | F43: =Startup!E$33*Assumptions!$B$47*(1+Assumptions!$B$46)^3 -> 17401.677 | G43: =Startup!E$33*Assumptions!$B$47*(1+Assumptions!$B$46)^4 -> 17923.728
A44: Insurance | C44: =(Assumptions!$B$64+Assumptions!$B$65*$B$4)*(1+Assumptions!$B$46)^0 -> 22000 | D44: =(Assumptions!$B$64+Assumptions!$B$65*$B$4)*(1+Assumptions!$B$46)^1 -> 22660 | E44: =(Assumptions!$B$64+Assumptions!$B$65*$B$4)*(1+Assumptions!$B$46)^2 -> 23339.8 | F44: =(Assumptions!$B$64+Assumptions!$B$65*$B$4)*(1+Assumptions!$B$46)^3 -> 24039.994 | G44: =(Assumptions!$B$64+Assumptions!$B$65*$B$4)*(1+Assumptions!$B$46)^4 -> 24761.194
A45: Marketing | C45: =C27*Assumptions!$B$66 -> 39552.285 | D45: =D27*Assumptions!$C$66 -> 43518.571 | E45: =E27*Assumptions!$D$66 -> 48554.547 | F45: =F27*Assumptions!$E$66 -> 48102.384 | G45: =G27*Assumptions!$F$66 -> 51962.562
...

Sheet Membership Tiers
A1: Membership Tiers & Blended Dues
A2: Edit price and target mix (blue). Blended dues feed the Assumptions sheet.
A4: Tier | B4: Monthly dues | C4: Annual prepaid | D4: Target mix | E4: Weighted dues | G4: What it includes
A5: Range (off-peak) | B5: 119 | C5: 1190 | D5: 0.3 | E5: =B5*D5 -> 35.7 | G5: Unlimited weekday 9am-4pm bay time; 20% off peak hourly; 10% F&B; app booking 7 days out
A6: Player | B6: 199 | C6: 1990 | D6: 0.45 | E6: =B6*D6 -> 89.55 | G6: Unlimited off-peak + 6 peak hrs/mo; book 10 days out; 2 guest passes/mo; league priority; 10% F&B; free bag storage
A7: Founders / Premier | B7: 299 | C7: 2400 | D7: 0.2 | E7: =B7*D7 -> 59.8 | G7: Unlimited any time; book 14 days out; 4 guest passes/mo; locker; annual fitting; 15% F&B; 1 event room booking/yr; name on founders wall
A8: Corporate (per seat, min 4) | B8: 249 | C8: 2490 | D8: 0.05 | E8: =B8*D8 -> 12.45 | G8: 4-10 seats; shared 12 peak hrs/mo; quarterly team event; invoiced; logo on league board
A10: Mix check (should be 100%) | D10: =SUM(D5:D8) -> 1
A12: Blended monthly dues | F12: =IF(D10=0,0,SUM(E5:E8)/D10) -> 197.5
A14: Youth / Family add-on | B14: 49 | G14: Under-18 add-on to any adult membership: junior league, 2 clinics/mo, academy content. Not in blended dues (upside).
A15: Scholarship member (Foundation-funded) | B15: 0 | G15: Foundation pays OpCo the Range rate for each scholarship youth member; shown as education revenue, not dues.

Sheet Foundation
A1: Foundation (501(c)(3)) — Education & Access Program Budget
A2: Separate entity. Buys bay time and staff time from OpCo. Year 1 can run under a fiscal sponsor (e.g., a community foundation) while the IRS determination is pending.
A4: ($, annual) | B4: Year 1 | C4: Year 2 | D4: Year 3 | E4: Notes / prospect
A5: PROGRAM VOLUME
A6: Students served (unique) | B6: 240 | C6: 480 | D6: 720 | E6: Field trips + after-school cohorts + summer academy + HS team practice
A7: Bay-hours purchased from OpCo | B7: ='P&L 4-Bay'!C12 -> 451.584 | C7: ='P&L 4-Bay'!D12 -> 846.72 | D7: ='P&L 4-Bay'!E12 -> 1128.96 | E7: Linked to 4-bay P&L education hours
A9: REVENUE / SUPPORT
A10: School division contracts (Hampton, Newport News, Portsmouth, Norfolk) | B10: 24000 | C10: 48000 | D10: 80000 | E10: Title IV-A, 21st CCLC, CTE work-based learning funds; ~$600 per 2-hr class block
A11: PGA REACH / First Tee / USGA grants | B11: 15000 | C11: 25000 | D11: 35000 | E11: PGA REACH (PGA WORKS, PGA Jr League scholarships); USGA IDEA grants; First Tee Hampton Roads partnership
A12: Corporate sponsors (banks, utilities, healthcare, defense contractors) | B12: 30000 | C12: 45000 | D12: 50000 | E12: TowneBank, Dominion Energy, Sentara, Newport News Shipbuilding, Langley credit unions; CRA credit for banks
A13: Community foundations | B13: 15000 | C13: 20000 | D13: 25000 | E13: Hampton Roads Community Foundation, Peninsula Community Foundation of Virginia
A14: Individual donors, alumni, HBCU networks | B14: 10000 | C14: 18000 | D14: 25000 | E14: Hampton University alumni, Divine Nine chapters, annual scramble fundraiser
A15: Program fees (sliding scale, summer academy) | B15: 8000 | C15: 15000 | D15: 24000 | E15: Full fee for families who can pay; scholarship for those who cannot
A16: Fundraising events (annual gala scramble, founders night) | B16: 12000 | C16: 20000 | D16: 28000
A17: TOTAL SUPPORT | B17: =SUM(B10:B16) -> 114000 | C17: =SUM(C10:C16) -> 191000 | D17: =SUM(D10:D16) -> 267000
A19: EXPENSES
A20: Bay time purchased from OpCo | B20: =B7*Assumptions!$B$12 -> 13547.52 | C20: =C7*Assumptions!$B$12*(1+Assumptions!$B$13) -> 26163.648 | D20: =D7*Assumptions!$B$12*(1+Assumptions!$B$13)^2 -> 35931.41 | E20: Education rate × hours (links to Assumptions)
A21: Director of Golf & Education (50% reimbursement to OpCo) | B21: =Assumptions!$B$51*Assumptions!$B$52*(1+Assumptions!$B$58) -> 33060 | C21: =Assumptions!$B$51*Assumptions!$B$52*(1+Assumptions!$B$58)*(1+Assumptions!$B$59) -> 34051.8 | D21: =Assumptions!$B$51*Assumptions!$B$52*(1+Assumptions!$B$58)*(1+Assumptions!$B$59)^2 -> 35073.354 | E21: Links to Assumptions payroll
A22: Program coordinator (PT → FT) | B22: 22000 | C22: 42000 | D22: 46000 | E22: Schedules schools, transportation, volunteers; AmeriCorps VISTA in Yr 1 if available
A23: Curriculum development & teacher stipends | B23: 12000 | C23: 15000 | D23: 15000 | E23: SOL-aligned math/science modules; GCSAA First Green materials
A24: Transportation (school buses, vans) | B24: 9000 | C24: 18000 | D24: 27000 | E24: Biggest hidden cost of any school partnership
A25: Youth equipment, gloves, balls, apparel | B25: 8000 | C25: 12000 | D25: 15000 | E25: US Kids Golf sets; partner discounts
A26: Scholarships (youth memberships, camps, caddie/PGM application support) | B26: 6000 | C26: 15000 | D26: 25000 | E26: Includes Evans Scholars and PGA WORKS Fellowship application coaching
A27: Career pathway events (superintendent days, HBCU golf visits, industry panel) | B27: 5000 | C27: 9000 | D27: 12000 | E27: Virginia Tech turfgrass, Hampton U golf, PGA WORKS Collegiate Championship
A28: Insurance, background checks, admin, audit | B28: 7000 | C28: 11000 | D28: 14000
A29: TOTAL EXPENSES | B29: =SUM(B20:B28) -> 115607.52 | C29: =SUM(C20:C28) -> 182215.45 | D29: =SUM(D20:D28) -> 225004.76
A31: Surplus / (deficit) | B31: =B17-B29 -> -1607.52 | C31: =C17-C29 -> 8784.552 | D31: =D17-D29 -> 41995.236 | E31: Target a modest surplus to build 3 months of reserve
A32: Cost per student served | B32: =IF(B6=0,0,B29/B6) -> 481.698 | C32: =IF(C6=0,0,C29/C6) -> 379.61552 | D32: =IF(D6=0,0,D29/D6) -> 312.50662 | E32: Funders benchmark youth sports/STEM programs at $250-$600 per student per year
A33: Cash paid to OpCo (bay time + salary reimbursement) | B33: =B20+B21 -> 46607.52 | C33: =C20+C21 -> 60215.448 | D33: =D20+D21 -> 71004.764 | E33: This is the mission's contribution to OpCo's fixed costs

Sheet Sensitivity
A1: Sensitivity — 4-Bay Year 3 EBITDA vs Utilization and Hourly Rate
A2: Approximation: base EBITDA plus the change in public bay revenue and F&B, net of variable costs. Does not re-run payroll.
A4: Base Year-3 EBITDA (4-bay) | B4: ='P&L 4-Bay'!E52 -> 220898.93
A5: Base utilization | B5: ='P&L 4-Bay'!E9 -> 0.4
A6: Base rate (Yr 3, escalated) | B6: =Assumptions!$B$11*(1+Assumptions!$B$13)^2 -> 47.7405
A7: Available bay-hours | B7: ='P&L 4-Bay'!B5 -> 20160
A8: Public share of used hours | B8: =1-Assumptions!$B$9-Assumptions!$D$10 -> 0.51
A9: F&B per used hour (Yr 3) | B9: =Assumptions!$D$35 -> 31
A10: Variable cost % of revenue (mkt+cc+r&m+misc) | B10: =Assumptions!$D$66+Assumptions!$B$67+Assumptions!$B$68+Assumptions!$B$69 -> 0.104
A11: F&B COGS % | B11: =Assumptions!$B$37 -> 0.34
A13: Utilization ↓ / Yr-1 public rate → | B13: 35 | C13: 40 | D13: 45 | E13: 50 | F13: 55
A14: 0.25 | B14: =$B$4+(($A14*B$13*(1+Assumptions!$B$13)^2-$B$5*$B$6)*$B$7*$B$8)*(1-$B$10)+(($A14-$B$5)*$B$7*$B$9)*(1-$B$11-$B$10) -> 78373.835 | C14: =$B$4+(($A14*C$13*(1+Assumptions!$B$13)^2-$B$5*$B$6)*$B$7*$B$8)*(1-$B$10)+(($A14-$B$5)*$B$7*$B$9)*(1-$B$11-$B$10) -> 90590.514 | D14: =$B$4+(($A14*D$13*(1+Assumptions!$B$13)^2-$B$5*$B$6)*$B$7*$B$8)*(1-$B$10)+(($A14-$B$5)*$B$7*$B$9)*(1-$B$11-$B$10) -> 102807.19 | E14: =$B$4+(($A14*E$13*(1+Assumptions!$B$13)^2-$B$5*$B$6)*$B$7*$B$8)*(1-$B$10)+(($A14-$B$5)*$B$7*$B$9)*(1-$B$11-$B$10) -> 115023.87 | F14: =$B$4+(($A14*F$13*(1+Assumptions!$B$13)^2-$B$5*$B$6)*$B$7*$B$8)*(1-$B$10)+(($A14-$B$5)*$B$7*$B$9)*(1-$B$11-$B$10) -> 127240.55
A15: 0.3 | B15: =$B$4+(($A15*B$13*(1+Assumptions!$B$13)^2-$B$5*$B$6)*$B$7*$B$8)*(1-$B$10)+(($A15-$B$5)*$B$7*$B$9)*(1-$B$11-$B$10) -> 112851.07 | C15: =$B$4+(($A15*C$13*(1+Assumptions!$B$13)^2-$B$5*$B$6)*$B$7*$B$8)*(1-$B$10)+(($A15-$B$5)*$B$7*$B$9)*(1-$B$11-$B$10) -> 127511.09 | D15: =$B$4+(($A15*D$13*(1+Assumptions!$B$13)^2-$B$5*$B$6)*$B$7*$B$8)*(1-$B$10)+(($A15-$B$5)*$B$7*$B$9)*(1-$B$11-$B$10) -> 142171.1 | E15: =$B$4+(($A15*E$13*(1+Assumptions!$B$13)^2-$B$5*$B$6)*$B$7*$B$8)*(1-$B$10)+(($A15-$B$5)*$B$7*$B$9)*(1-$B$11-$B$10) -> 156831.12 | F15: =$B$4+(($A15*F$13*(1+Assumptions!$B$13)^2-$B$5*$B$6)*$B$7*$B$8)*(1-$B$10)+(($A15-$B$5)*$B$7*$B$9)*(1-$B$11-$B$10) -> 171491.13
A16: 0.35 | B16: =$B$4+(($A16*B$13*(1+Assumptions!$B$13)^2-$B$5*$B$6)*$B$7*$B$8)*(1-$B$10)+(($A16-$B$5)*$B$7*$B$9)*(1-$B$11-$B$10) -> 147328.31 | C16: =$B$4+(($A16*C$13*(1+Assumptions!$B$13)^2-$B$5*$B$6)*$B$7*$B$8)*(1-$B$10)+(($A16-$B$5)*$B$7*$B$9)*(1-$B$11-$B$10) -> 164431.66 | D16: =$B$4+(($A16*D$13*(1+Assumptions!$B$13)^2-$B$5*$B$6)*$B$7*$B$8)*(1-$B$10)+(($A16-$B$5)*$B$7*$B$9)*(1-$B$11-$B$10) -> 181535.02 | E16: =$B$4+(($A16*E$13*(1+Assumptions!$B$13)^2-$B$5*$B$6)*$B$7*$B$8)*(1-$B$10)+(($A16-$B$5)*$B$7*$B$9)*(1-$B$11-$B$10) -> 198638.37 | F16: =$B$4+(($A16*F$13*(1+Assumptions!$B$13)^2-$B$5*$B$6)*$B$7*$B$8)*(1-$B$10)+(($A16-$B$5)*$B$7*$B$9)*(1-$B$11-$B$10) -> 215741.72
A17: 0.4 | B17: =$B$4+(($A17*B$13*(1+Assumptions!$B$13)^2-$B$5*$B$6)*$B$7*$B$8)*(1-$B$10)+(($A17-$B$5)*$B$7*$B$9)*(1-$B$11-$B$10) -> 181805.55 | C17: =$B$4+(($A17*C$13*(1+Assumptions!$B$13)^2-$B$5*$B$6)*$B$7*$B$8)*(1-$B$10)+(($A17-$B$5)*$B$7*$B$9)*(1-$B$11-$B$10) -> 201352.24 | D17: =$B$4+(($A17*D$13*(1+Assumptions!$B$13)^2-$B$5*$B$6)*$B$7*$B$8)*(1-$B$10)+(($A17-$B$5)*$B$7*$B$9)*(1-$B$11-$B$10) -> 220898.93 | E17: =$B$4+(($A17*E$13*(1+Assumptions!$B$13)^2-$B$5*$B$6)*$B$7*$B$8)*(1-$B$10)+(($A17-$B$5)*$B$7*$B$9)*(1-$B$11-$B$10) -> 240445.61 | F17: =$B$4+(($A17*F$13*(1+Assumptions!$B$13)^2-$B$5*$B$6)*$B$7*$B$8)*(1-$B$10)+(($A17-$B$5)*$B$7*$B$9)*(1-$B$11-$B$10) -> 259992.3
A18: 0.45 | B18: =$B$4+(($A18*B$13*(1+Assumptions!$B$13)^2-$B$5*$B$6)*$B$7*$B$8)*(1-$B$10)+(($A18-$B$5)*$B$7*$B$9)*(1-$B$11-$B$10) -> 216282.79 | C18: =$B$4+(($A18*C$13*(1+Assumptions!$B$13)^2-$B$5*$B$6)*$B$7*$B$8)*(1-$B$10)+(($A18-$B$5)*$B$7*$B$9)*(1-$B$11-$B$10) -> 238272.81 | D18: =$B$4+(($A18*D$13*(1+Assumptions!$B$13)^2-$B$5*$B$6)*$B$7*$B$8)*(1-$B$10)+(($A18-$B$5)*$B$7*$B$9)*(1-$B$11-$B$10) -> 260262.84 | E18: =$B$4+(($A18*E$13*(1+Assumptions!$B$13)^2-$B$5*$B$6)*$B$7*$B$8)*(1-$B$10)+(($A18-$B$5)*$B$7*$B$9)*(1-$B$11-$B$10) -> 282252.86 | F18: =$B$4+(($A18*F$13*(1+Assumptions!$B$13)^2-$B$5*$B$6)*$B$7*$B$8)*(1-$B$10)+(($A18-$B$5)*$B$7*$B$9)*(1-$B$11-$B$10) -> 304242.88
A19: 0.5 | B19: =$B$4+(($A19*B$13*(1+Assumptions!$B$13)^2-$B$5*$B$6)*$B$7*$B$8)*(1-$B$10)+(($A19-$B$5)*$B$7*$B$9)*(1-$B$11-$B$10) -> 250760.03 | C19: =$B$4+(($A19*C$13*(1+Assumptions!$B$13)^2-$B$5*$B$6)*$B$7*$B$8)*(1-$B$10)+(($A19-$B$5)*$B$7*$B$9)*(1-$B$11-$B$10) -> 275193.39 | D19: =$B$4+(($A19*D$13*(1+Assumptions!$B$13)^2-$B$5*$B$6)*$B$7*$B$8)*(1-$B$10)+(($A19-$B$5)*$B$7*$B$9)*(1-$B$11-$B$10) -> 299626.75 | E19: =$B$4+(($A19*E$13*(1+Assumptions!$B$13)^2-$B$5*$B$6)*$B$7*$B$8)*(1-$B$10)+(($A19-$B$5)*$B$7*$B$9)*(1-$B$11-$B$10) -> 324060.11 | F19: =$B$4+(($A19*F$13*(1+Assumptions!$B$13)^2-$B$5*$B$6)*$B$7*$B$8)*(1-$B$10)+(($A19-$B$5)*$B$7*$B$9)*(1-$B$11-$B$10) -> 348493.47
A21: Read: each cell is Year-3 EBITDA for the 4-bay plan at that utilization and public hourly rate. Compare to annual debt service on the Startup sheet.
